terminate called after throwing an instance of 'std::runtime_error'
  what():  could not open out_2024-08-27/asm_test/riscv_arithmetic_basic_test_1.o (did you misspell it? If VCS, did you forget +permissive/+permissive-off?)
